Workbook

Sheet Que of the assignment
B3: Assignment Question: Merger Model for LinkedIn and Microsoft Deal
B5: Objective:
B6: Candidates are required to prepare a detailed merger model for the acquisition of LinkedIn by Microsoft, which was announced on June 13, 2016. The model should incorporate both qualitative and quantitative analysis to provide a comprehensive overview of the deal.
B8: Instructions:
B10: 1. Introduction:
B11: Provide a brief introduction to LinkedIn and Microsoft.
B12: Outline the strategic rationale behind the merger.
B13: Mention the key terms of the deal, including the acquisition price and method of payment.
B15: 2. Historical Financial Analysis:
B16: Analyze the historical financial statements of both companies for the past three years.
B17: Include income statements, balance sheets, and cash flow statements.
B18: Calculate key financial ratios and metrics to understand the financial health and performance pre-merger.
... B33: An Excel model with all calculations and financial statements.

Sheet Introduction
B2: Merger model of Microsoft & Linked In
B3: Acquirer Company : Microsoft (MSFT)
B4: Tartget Company : LinkedIn (LNKD)
B6: Microsoft Corporation | D6: LinkedIn Corporation
B7: Founded: 1975 | D7: Founded: 2002
B8: Headquarters: Redmond, Washington | D8: Headquarters: Sunnyvale, California
B9: Key Products: Windows OS, Microsoft Office, Azure Cloud, Dynamics CRM | D9: Users (2016): Over 433 million members
B10: Business model | D10: Business Model:
B11: Software and cloud services | D11: Professional networking
B12: Enterprise solutions | D12: Job listings
B13: Hardware and devices | D13: Premium subscriptions
B14: Strategic Focus (2016): Cloud computing, AI, productivity tools, and enterprise | D14: Talent and marketing solutions
B15: integration | D15: Core Strength: Largest global platform for professionals to connect, learn, and find opportunities
B18: Key Details of the Acquisition:
B19: Transaction Value: $26.2 billion, including LinkedIn's net cash.
B20: Price per Share: $196.
B21: Leadership: Jeff Weiner to remain LinkedIn CEO, reporting to Satya Nadella.
B22: Brand and Independence: LinkedIn to retain its distinct brand, culture, and independence.
B23: Strategic Fit: Microsoft aimed to integrate LinkedIn with its enterprise software, like Office 365, and leverage its large user base.
B25: Analyst Commentary:
B26: Analysts noted that Microsoft could build LinkedIn into a major customer relationship management (CRM) platform, competing with Salesforce.
B27: Some analysts also pointed out that the deal gave Microsoft access to the world's largest professional social network .
B29: Impact on Microsoft and LinkedIn:
B30: Microsoft: Gained access to LinkedIn's massive user base and a prominent professional networking platform, strengthening its enterprise offerings.
B31: LinkedIn: Benefited from Microsoft's resources and support, accelerating its growth and expanding its global reach.

Sheet Synergies
B4: On Monday, June 13, 2016, Microsoft (MSFT) announced the acquisition of LinkedIn for $26.2 billion in an all-cash transaction, valuing each share at $196. The deal was fully supported by LinkedIn's chairman and co-founder, Reid Hoffman, and CEO, Jeff Weiner, who would remain in his role and report to Microsoft CEO Satya Nadella. LinkedIn would retain its distinct brand, culture, and independence.
B7: Strategic Rationale Behind the Merger
B8: The acquisition of LinkedIn by Microsoft in June 2016 for $26.2 billion was driven by a shared vision: to connect the world's leading professional cloud with the world's leading professional network. The strategic rationale includes the following key points:
B10: 🔗 1. Synergy Between Products and Platforms
B11: Microsoft aimed to integrate LinkedIn’s professional graph with its productivity suite (Office 365, Outlook, Dynamics CRM).
B12: This would help users enhance their work through intelligent insights, networking, and collaboration.
B13: 📈 2. Accelerated Engagement and Growth
B14: LinkedIn had shown strong user growth and engagement:
B15: 19% growth in total membership
B16: 49% growth in mobile usage
B17: 101% increase in job listings
B18: Microsoft could leverage this momentum to boost both companies’ reach and user base.
... B48: Facilitating communication with regulators and shareholders

Sheet Microsoft  acquirer
A2: Merger model of Microsoft & Linked In
A3: Acquirer Company : Microsoft (MSFT)
A4: Tartget Company : LinkedIn (LNKD)
A5: Date of Acquisition : 13/06/2016
A6: Price of acquisition : $26.2 Billion
A7: ($ in million except per share data)
A9: Acquirer details
B11: Latest Financials available | D11: 42551 | G11: Capitalisation of Lease
B12: Unaffected share price | D12: 48.03 | G12: Year | H12: Amount | I12: lease committed
B13: Transaction date share price | D13: 50.14 | G13: 2016 | H13: 863
B14: Tax rate | D14: 0.34 | G14: =G13+1 -> 2017 | H14: 803
G15: =G14+1 -> 2018 | H15: 735
B16: Basic shares outstaning | D16: 8177 | G16: =G15+1 -> 2019 | H16: 611
B17: Dilutive shares outstanding | D17: 8254 | G17: =G16+1 -> 2020 | H17: 524 | I17: 1617
G18: =G17+1 -> 2021 | H18: 524 | I18: =I17-H18 -> 1093
B19: Equity value on date on transaction | D19: =D17*D13 -> 413855.56 | G19: =G18+1 -> 2022 | H19: 524 | I19: =I18-H19 -> 569
B20: Less: Cash | D20: -5595 | G20: =G19+1 -> 2023 | H20: 524 | I20: =I19-H20 -> 45
B21: Less: Investments | D21: -90931 | G21: =G20+1 -> 2024 | H21: 45 | I21: =I20-H21 -> 0
B22: Add: Debt | D22: =4985+2499+27808 -> 35292
B23: Add: Capitalisation of lease | D23: =H24 -> 4716.5213 | G23: cost of debt | H23: =I27/I26 -> 0.022129661
B24: Add: Preference shares | D24: 0 | G24: PV of lease obligation | H24: =NPV(H23,H13:H21) -> 4716.5213
B25: Add: NCI | D25: 0
B26: Add: Unfunded pension obligation | D26: 0 | G26: total debt | I26: =D22 -> 35292
B27: Enterprise value | D27: =SUM(D19:D26) -> 357338.08 | G27: Interest expense | I27: 781
G28: cost of debt | I28: =I27/I26 -> 0.022129661
A30: Acquirers Income Statement | F30: Historical | J30: Projection
A31: (In millions) | E31: 2013 | F31: =E31+1 -> 2014 | G31: =F31+1 -> 2015 | H31: =G31+1 -> 2016 | I31: =H31+1 -> 2017 | J31: =I31+1 -> 2018 | K31: =J31+1 -> 2019 | L31: =K31+1 -> 2020
B33: Revenue | D33: 73723 | E33: 77849 | F33: 86833 | G33: 93580 | H33: =G33*(1+H61) -> 100851.25 | I33: =H33*(1+I61) -> 108687.48 | J33: =I33*(1+J61) -> 117132.59 | K33: =J33*(1+K61) -> 126233.89 | L33: =K33*(1+L61) -> 136042.38
B34: Cost of revenue | D34: 17530 | E34: 20385 | F34: 27078 | G34: 33038 | H34: =H33*H62 -> 31154.247 | I34: =I33*I62 -> 35279.895 | J34: =J33*J62 -> 38519.358 | K34: =K33*K62 -> 40494.357 | L34: =L33*L62 -> 44179.325
B35: Gross margin | D35: =D33-D34 -> 56193 | E35: =E33-E34 -> 57464 | F35: =F33-F34 -> 59755 | G35: =G33-G34 -> 60542 | H35: =H33-H34 -> 69697.001 | I35: =I33-I34 -> 73407.582 | J35: =J33-J34 -> 78613.232 | K35: =K33-K34 -> 85739.538 | L35: =L33-L34 -> 91863.053
B37: Research and development | E37: 10411 | F37: 11381 | G37: 12046 | H37: =H33*H63 -> 13229.163 | I37: =I33*I63 -> 14257.081 | J37: =J33*J63 -> 15364.868 | K37: =K33*K63 -> 16558.732 | L37: =L33*L63 -> 17845.36
B38: Sales and marketing | E38: 15276 | F38: 15811 | G38: 15713 | H38: =H33*H64 -> 18362.356 | I38: =I33*I64 -> 19276.399 | J38: =J33*J64 -> 20589.554 | K38: =K33*K64 -> 22520.538 | L38: =L33*L64 -> 24103.959
B39: General and administrative | E39: 5013 | F39: 4677 | G39: 4611 | H39: =H33*H65 -> 5631.8447 | I39: =I33*I65 -> 5759.6554 | J39: =J33*J65 -> 6173.2485 | K39: =K33*K65 -> 6797.2315 | L39: =L33*L65 -> 7234.8345
B40: Impairment, integration, and restructuring | E40: 0 | F40: 127 | G40: 10011 | H40: 0 | I40: 0 | J40: 0 | K40: 0 | L40: 0
B41: Operating income Ebit | E41: =E35-SUM(E37:E40) -> 26764 | F41: =F35-SUM(F37:F40) -> 27759 | G41: =G35-SUM(G37:G40) -> 18161 | H41: =H35-SUM(H37:H40) -> 32473.637 | I41: =I35-SUM(I37:I40) -> 34114.447 | J41: =J35-SUM(J37:J40) -> 36485.561 | K41: =K35-SUM(K37:K40) -> 39863.036 | L41: =L35-SUM(L37:L40) -> 42678.899
B42: Other income, net | E42: 288 | F42: 61 | G42: 346 | H42: =H41*H67 -> 346.49396 | I42: =I41*I67 -> 362.96985 | J42: =J41*J67 -> 490.87177 | K42: =K41*K67 -> 461.92809 | L42: =L41*L67 -> 507.6159
B44: Income before income taxes | D44: ` | E44: =E41+E42 -> 27052 | F44: =F41+F42 -> 27820 | G44: =G41+G42 -> 18507 | H44: =H41+H42 -> 32820.131 | I44: =I41+I42 -> 34477.417 | J44: =J41+J42 -> 36976.433 | K44: =K41+K42 -> 40324.964 | L44: =L41+L42 -> 43186.515
B45: Provision for income taxes | E45: 5189 | F45: 5746 | G45: 6314 | H45: =H66*H44 -> 8090.447 | I45: =I66*I44 -> 8498.9825 | J45: =J66*J44 -> 9115.0115 | K45: =K66*K44 -> 9940.4536 | L45: =L66*L44 -> 10645.851
B46: Net income | E46: =E44-E45 -> 21863 | F46: =F44-F45 -> 22074 | G46: =G44-G45 -> 12193 | H46: =H44-H45 -> 24729.684 | I46: =I44-I45 -> 25978.435 | J46: =J44-J45 -> 27861.421 | K46: =K44-K45 -> 30384.511 | L46: =L44-L45 -> 32540.664
B48: Earnings per share:
...

Sheet Linked in Target
A2: Merger model of Microsoft & Linked In
A3: Acquirer Company : Microsoft (MSFT)
A4: Tartget Company : LinkedIn (LNKD)
A5: Date of Acquisition : 13/06/2016
A6: Price of acquisition : $26.2 Billion
A7: ($ in million except per share data)
A9: Targets Details
B11: Latest Financials available | F11: 42369 | J11: Capitalisation of leases
B12: Unaffected share price | F12: 131.08 | J12: Year | L12: amount | M12: Lease committed
B13: Transaction date share price | F13: 196 | J13: 2016 | L13: =141471/10^3 -> 141.471
B14: Tax rate | F14: 0.23 | J14: =J13+1 -> 2017 | L14: =150087/10^3 -> 150.087
J15: =J14+1 -> 2018 | L15: 177
B16: Basic shares outstaning | F16: =129024/10^3 -> 129.024 | J16: =J15+1 -> 2019 | L16: 181
B17: Dilutive shares outstanding | F17: =129024/10^3 -> 129.024 | J17: =J16+1 -> 2020 | L17: 175 | M17: =993730/10^3 -> 993.73
J18: =J17+1 -> 2021 | L18: 175 | M18: =M17-L18 -> 818.73
J19: =J18+1 -> 2022 | L19: 175 | M19: =M18-L19 -> 643.73
B20: Equity value on date on transaction | F20: =F17*F13 -> 25288.704 | J20: =J19+1 -> 2023 | L20: 175 | M20: =M19-L20 -> 468.73
B21: Less: Cash | F21: =546237/10^3 -> 546.237 | J21: =J20+1 -> 2024 | L21: 175 | M21: =M20-L21 -> 293.73
B22: Less: Investments | F22: =2573145/10^3 -> 2573.145 | J22: =J21+1 -> 2025 | L22: 175 | M22: =M21-L22 -> 118.73
B23: Add: Debt | F23: =1126534/10^3 -> 1126.534 | J23: =J22+1 -> 2026 | L23: 119 | M23: =M22-L23 -> -0.27
B24: Add: Capitalisation of lease | F24: =L27 -> 1408.6829
B25: Add: Preference shares | F25: 0
B26: Add: NCI | F26: =26810/10^3 -> 26.81 | J26: Cost of debt | L26: =L31 -> 0.045166857
B27: Add: Unfunded pension obligation | F27: 0 | J27: PV of lease obligation | L27: =NPV(L26,L13:L23) -> 1408.6829
B28: Enterprise value | F28: =SUM(F20:F27) -> 30970.113
J29: total debt | L29: =F23 -> 1126.534
J30: interest expense | L30: =50882/10^3 -> 50.882
J31: Cost of debt | L31: =L30/L29 -> 0.045166857
A33: Targets Income Statement | H33: Historical | L33: Projection
A34: (In millions) | G34: 2013 | H34: =G34+1 -> 2014 | I34: =H34+1 -> 2015 | J34: =I34+1 -> 2016 | K34: =J34+1 -> 2017 | L34: =K34+1 -> 2018 | M34: =L34+1 -> 2019 | N34: =M34+1 -> 2020
B36: Net revenue | F36: 972309 | G36: 1528545 | H36: 2218767 | I36: 2990911 | J36: =I36*(1+J69) -> 4358393.6 | K36: =J36*(1+K69) -> 6184231.5 | L36: =K36*(1+L69) -> 8707693.1 | M36: =L36*(1+M69) -> 12435123 | N36: =M36*(1+N69) -> 17637289
B37: Cost of revenue | F37: 125521 | G37: 202908 | H37: 293797 | I37: 418858 | J37: =J36*J70 -> 588679.51 | K37: =K36*K70 -> 840078.69 | L37: =L36*L70 -> 1192819.5 | M37: =M36*M70 -> 1690739.8 | N37: =N36*N70 -> 2403324.5
B38: Gross Profit | F38: =F36-F37 -> 846788 | G38: =G36-G37 -> 1325637 | H38: =H36-H37 -> 1924970 | I38: =I36-I37 -> 2572053 | J38: =J36-J37 -> 3769714.1 | K38: =K36-K37 -> 5344152.8 | L38: =L36-L37 -> 7514873.6 | M38: =M36-M37 -> 10744383 | N38: =N36-N37 -> 15233965
B40: Sales and marketing | G40: 522100 | H40: 774411 | I40: 1048129 | J40: =J36*J71 -> 1512409.6 | K40: =K36*K71 -> 2157217.6 | L40: =L36*L71 -> 3036878.5 | M40: =M36*M71 -> 4329886.3 | N40: =N36*N71 -> 6148251.5
B41: Product development | G41: 395643 | H41: 536184 | I41: 775660 | J41: =J36*J72 -> 1103885.1 | K41: =K36*K72 -> 1554871.6 | L41: =L36*L72 -> 2217681.7 | M41: =M36*M72 -> 3147677.3 | N41: =N36*N72 -> 4463609.3
B42: General and administrative | G42: 225566 | H42: 341294 | I42: 478734 | J42: =J36*J73 -> 670398.66 | K42: =K36*K73 -> 964126.31 | L42: =L36*L73 -> 1363571.1 | M42: =M36*M73 -> 1932884 | N42: =N36*N73 -> 2751017.7
B43: Depreciation and amortization | G43: 134516 | H43: 236946 | I43: 420472 | J43: =J36*J74 -> 487235.92 | K43: =K36*K74 -> 740391.75 | L43: =L36*L74 -> 1080039.3 | M43: =M36*M74 -> 1473760.3 | N43: =N36*N74 -> 2129827.5
B44: Total costs and expenses | G44: =SUM(G40:G43) -> 1277825 | H44: =SUM(H40:H43) -> 1888835 | I44: =SUM(I40:I43) -> 2722995 | J44: =SUM(J40:J43) -> 3773929.2 | K44: =SUM(K40:K43) -> 5416607.2 | L44: =SUM(L40:L43) -> 7698170.6 | M44: =SUM(M40:M43) -> 10884208 | N44: =SUM(N40:N43) -> 15492706
B45: Income (loss) from operations (EBIT) | G45: =G38-G44 -> 47812 | H45: =H38-H44 -> 36135 | I45: =I38-I44 -> -150942 | J45: =J38-J44 -> -4215.1567 | K45: =K38-K44 -> -72454.376 | L45: =L38-L44 -> -183297 | M45: =M38-M44 -> -139825.2 | N45: =N38-N44 -> -258741.21
B46: Other income (expense), net:
...

Sheet Merger Model
A3: Merger model of Microsoft & Linked In
A4: Acquirer Company : Microsoft (MSFT)
A5: Tartget Company : LinkedIn (LNKD)
A6: ($ in million except per share data)
A8: Transacation assumptions
B10: Date of announcement of merger | G10: June 13, 2016
B11: Date of complition of merger | G11: Dec 08, 2016
I12: %Cash | J12: 0 | L12: Particular | N12: Amount | O12: Pre-tax cost | P12: Tax rate of acquirer | Q12: Post tax cost
B13: Acquirer Company | G13: Microsoft Corp. | I13: %Debt | J13: 1 | L13: Cash used | N13: =J12*G27 -> 0 | O13: =766/AVERAGE('Microsoft acquirer'!F88:G88) -> 0.10740325 | P13: ='Microsoft acquirer'!$D$14 -> 0.34 | Q13: =O13*(1-P13) -> 0.070886147
B14: Acquirer's Ticker | G14: (Nasdaq: MSFT) | I14: %Stock | J14: 0 | L14: Debt used | N14: =J13*G27 -> 25288.704 | O14: 0.027 | P14: ='Microsoft acquirer'!$D$14 -> 0.34 | Q14: =O14*(1-P14) -> 0.01782
L15: Stock used | N15: 0 | P15: ='Microsoft acquirer'!$D$14 -> 0.34 | Q15: ='Microsoft acquirer'!G50/'Microsoft acquirer'!D13 -> 0.02946197
B16: Tartget Company | G16: LinkedIn Corporation | L16: No. of share issued
B17: Target's Ticker | G17: (NYSE: LNKD) | L17: Weighted average cost of fund | Q17: =SUMPRODUCT(N13:N15,Q13:Q15)/SUM(N13:N15) -> 0.01782
B19: Unaffected share price | G19: 131 | L19: Year | M19: 2017 | N19: 2018 | O19: 2019 | P19: 2020
B20: Offer Price | G20: 196 | L20: COGS Synergies | M20: 30 | N20: 30 | O20: 30 | P20: 30
B21: Premium | G21: =G20-G19 -> 65
B22: Premium % | G22: =G21/G19 -> 0.49618321
I23: EMI | J23: =PMT(O14,G32,-N14,0,0) -> 5474.692 | L23: Year | M23: EMI | N23: Interest | O23: Principal | P23: closing balance
B24: Equity Value | L24: 2017 | M24: =$J$23 -> 5474.692 | N24: =O14*N14 -> 682.79501 | O24: =M24-N24 -> 4791.897 | P24: =N14-O24 -> 20496.807
B25: No.of Diluted shares outstanding | G25: ='Linked in Target'!F17 -> 129.024 | L25: =L24+1 -> 2018 | M25: =$J$23 -> 5474.692 | N25: =P24*$O$14 -> 553.41379 | O25: =M25-N25 -> 4921.2782 | P25: =P24-O25 -> 15575.529
L26: =L25+1 -> 2019 | M26: =$J$23 -> 5474.692 | N26: =P25*$O$14 -> 420.53928 | O26: =M26-N26 -> 5054.1527 | P26: =P25-O26 -> 10521.376
B27: purchase equity value | G27: ='Linked in Target'!F20 -> 25288.704 | L27: =L26+1 -> 2020 | M27: =$J$23 -> 5474.692 | N27: =P26*$O$14 -> 284.07716 | O27: =M27-N27 -> 5190.6148 | P27: =P26-O27 -> 5330.7614
B28: purchase enterprice value | G28: ='Linked in Target'!$F$28 -> 30970.113 | L28: =L27+1 -> 2021 | M28: =$J$23 -> 5474.692 | N28: =P27*$O$14 -> 143.93056 | O28: =M28-N28 -> 5330.7614 | P28: =P27-O28 -> 0
B30: Advisory fees | G30: 0.01
B31: Debt Issuance fees | G31: 0.03
B32: Amortization period (year) | G32: 5
B34: Minimum cash balance of combined company | G34: 1000
B35: Pre-deal cash balance of combined company | G35: 97072
A37: Sources and uses of fund
C39: Sources of Funds | J39: Uses of Funds
B40: Cash | E40: =N13 -> 0 | I40: Equity purchase price | K40: ` | L40: =G27 -> 25288.704
B41: Debt | E41: =N14 -> 25288.704 | I41: Advisory fees | L41: =G30*L40 -> 252.88704
B42: Equity | E42: =N15 -> 0 | I42: Debt issuance fees | L42: =G31*N14 -> 758.66112
B43: Excess Cash | E43: =E44-SUM(E40:E42) -> 859.81594 | I43: Refinancing of acquirer's debt
B44: Total | E44: =L44 -> 26148.52 | I44: Total | L44: 26148.52
A46: Purchase Price Allocation
I47: `
B48: Calculation of goodwill: | I48: Fixed Asset writeup
B49: Equity Purchase price | F49: =G27 -> 25288.704 | I49: PPE writeup in % | K49: 0.1
B50: Less: Book value of target's equity | F50: ='Linked in Target'!I128/10^3 -> 4468.643 | I50: PPE writeup in amount | K50: =K49*'Linked in Target'!I109/10^3 -> 104.7005
...

Sheet Combine balance sheet
A2: Merger model of Microsoft & Linked In
A3: Acquirer Company : Microsoft (MSFT)
A4: Tartget Company : LinkedIn (LNKD)
A5: Date of Acquisition : 13/06/2016
A6: Price of acquisition : $26.2 Billion
A7: (In millions)
A9: Combined balance sheet | E9: 2016 | F9: 2016 | G9: Debit | H9: Credit | J9: 2016
A10: (In millions) | E10: Buyer | F10: Seller | G10: Proforma Adjustments | J10: Combined balance sheet
B12: ASSETS | E12: `
B13: Current Assets
B14: Cash and cash equivalents | E14: 6510 | F14: 546.24 | G14: 0 | H14: ='Merger Model'!E43 -> 859.81594 | J14: =SUM(E14:H14) -> 7916.0559
B15: Short-term investments | E15: 106730 | F15: 2573.15 | G15: 0 | H15: 0 | J15: =SUM(E15:H15) -> 109303.15
B16: Accounts receivable | E16: 18277 | F16: 603.06 | G16: 0 | H16: 0 | J16: =SUM(E16:H16) -> 18880.06
B17: Inventories | E17: 2251 | F17: - | G17: 0 | H17: 0 | J17: =SUM(E17:H17) -> 2251
B18: Deferred commissions | E18: - | F18: 87.71 | G18: 0 | H18: 0 | J18: =SUM(E18:H18) -> 87.71
B19: Other Current Assets and Prepaid Expenses | E19: 5892 | F19: 124.94 | G19: 0 | H19: 0 | J19: =SUM(E19:H19) -> 6016.94
B20: Total current assets | E20: =SUM(E14:E19) -> 139660 | F20: =SUM(F14:F19) -> 3935.1 | J20: =SUM(E20:H20) -> 143595.1
B22: Non-Current Assets
B23: Property and equipment, net | E23: 18356 | F23: 1047.01 | G23: ='Merger Model'!$K$50 -> 104.7005 | H23: 0 | J23: =SUM(E23:H23) -> 19507.71
B24: Goodwill | E24: 17872 | F24: 1507.09 | G24: ='Merger Model'!$F$58 -> 15725.632 | J24: =SUM(E24:H24) -> 35104.722
B25: Intangible assets, net | E25: 3733 | F25: 373.09 | G25: 7887 | H25: 0 | J25: =SUM(E25:H25) -> 11993.09
B26: Equity and other investments | E26: 10431 | F26: - | G26: 0 | H26: 0 | J26: =SUM(E26:H26) -> 10431
B27: Other long-term assets | E27: 3642 | F27: 148.93 | G27: 0 | H27: 0 | J27: =SUM(E27:H27) -> 3790.93
B28: Total assets | E28: =SUM(E20:E27) -> 193694 | F28: =SUM(F20:F27) -> 7011.22 | G28: 0 | H28: 0 | J28: =SUM(E28:H28) -> 200705.22
B30: LIABILITY AND EQUITY
B31: Current Liability
B32: Accounts payables | E32: 6898 | F32: 162.18 | G32: 0 | H32: 0 | J32: =SUM(E32:H32) -> 7060.18
B33: Short-term debt | E33: 12904 | F33: - | G33: 0 | H33: 0 | J33: =SUM(E33:H33) -> 12904
B34: Accrued compensation | E34: 5264 | F34: - | G34: 0 | H34: 0 | J34: =SUM(E34:H34) -> 5264
B35: Accrued liabilities | E35: - | F35: 316.79 | G35: 0 | H35: 0 | J35: =SUM(E35:H35) -> 316.79
B36: Income taxes | E36: 580 | F36: - | G36: 0 | H36: 0 | J36: =SUM(E36:H36) -> 580
B37: Short-term unearned revenue | E37: 27468 | F37: - | G37: 0 | H37: 0 | J37: =SUM(E37:H37) -> 27468
B38: Securities lending payable | E38: 294 | F38: - | G38: 0 | H38: 0 | J38: =SUM(E38:H38) -> 294
B39: Other | E39: 5949 | F39: - | G39: 0 | H39: 0 | J39: =SUM(E39:H39) -> 5949
B40: Deferred revenue | E40: - | F40: 709.12 | G40: 0 | H40: 0 | J40: =SUM(E40:H40) -> 709.12
B41: Total Current Liability | E41: =SUM(E32:E40) -> 59357 | F41: =SUM(F32:F40) -> 1188.09 | G41: 0 | H41: 0 | J41: =SUM(E41:H41) -> 60545.09
B43: Non-Current Liability
B44: New debt taken | E44: 0 | F44: 0 | H44: ='Merger Model'!N14 -> 25288.704 | J44: =SUM(E44:H44) -> 25288.704
B45: Long-term debt | E45: 40783 | F45: 1126.53 | G45: =-F45 -> -1126.53 | H45: ='Merger Model'!F57 -> 2717.1782 | J45: =SUM(E45:H45) -> 43500.178
B46: Long-term unearned revenue | E46: 6441 | F46: - | G46: 0 | H46: 0 | J46: =SUM(E46:H46) -> 6441
...
